Workbook
Name Slicer_Age: #N/A
Name Slicer_Business_Unit: #N/A
Name Slicer_Country: #N/A
Name Slicer_Country1: #N/A
Name Slicer_Department: #N/A
Name Slicer_Gender: #N/A

Sheet DashBoard

Sheet Main
A1: EEID | B1: Full Name | C1: Job Title | D1: Department | E1: Business Unit | F1: Gender | G1: Age | H1: Hire Date | I1: Annual Salary | J1: Bonus % | K1: Country | L1: City
A2: E02387 | B2: Emily Davis | C2: Sr. Manger | D2: IT | E2: Research & Development | F2: Female | G2: 55 | H2: 08-04-2016 | I2: 141604 | J2: 0.15 | K2: United States | L2: Seattle
A3: E04105 | B3: Theodore Dinh | C3: Technical Architect | D3: IT | E3: Manufacturing | F3: Male | G3: 59 | H3: 29-11-1997 | I3: 99975 | J3: 0 | K3: China | L3: Chongqing
A4: E02572 | B4: Luna Sanders | C4: Director | D4: Finance | E4: Speciality Products | F4: Female | G4: 50 | H4: 26-10-2006 | I4: 163099 | J4: 0.2 | K4: United States | L4: Chicago
A5: E02832 | B5: Penelope Jordan | C5: Computer Systems Manager | D5: IT | E5: Manufacturing | F5: Female | G5: 26 | H5: 27-09-2019 | I5: 84913 | J5: 0.07 | K5: United States | L5: Chicago
A6: E01639 | B6: Austin Vo | C6: Sr. Analyst | D6: Finance | E6: Manufacturing | F6: Male | G6: 55 | H6: 20-11-1995 | I6: 95409 | J6: 0 | K6: United States | L6: Phoenix
A7: E00644 | B7: Joshua Gupta | C7: Account Representative | D7: Sales | E7: Corporate | F7: Male | G7: 57 | H7: 24-01-2017 | I7: 50994 | J7: 0 | K7: China | L7: Chongqing
A8: E01550 | B8: Ruby Barnes | C8: Manager | D8: IT | E8: Corporate | F8: Female | G8: 27 | H8: 01-07-2020 | I8: 119746 | J8: 0.1 | K8: United States | L8: Phoenix
A9: E04332 | B9: Luke Martin | C9: Analyst | D9: Finance | E9: Manufacturing | F9: Male | G9: 25 | H9: 16-05-2020 | I9: 41336 | J9: 0 | K9: United States | L9: Miami
A10: E04533 | B10: Easton Bailey | C10: Manager | D10: Accounting | E10: Manufacturing | F10: Male | G10: 29 | H10: 25-01-2019 | I10: 113527 | J10: 0.06 | K10: United States | L10: Austin
A11: E03838 | B11: Madeline Walker | C11: Sr. Analyst | D11: Finance | E11: Speciality Products | F11: Female | G11: 34 | H11: 13-06-2018 | I11: 77203 | J11: 0 | K11: United States | L11: Chicago
A12: E00591 | B12: Savannah Ali | C12: Sr. Manger | D12: Human Resources | E12: Manufacturing | F12: Female | G12: 36 | H12: 11-02-2009 | I12: 157333 | J12: 0.15 | K12: United States | L12: Miami
A13: E03344 | B13: Camila Rogers | C13: Controls Engineer | D13: Engineering | E13: Speciality Products | F13: Female | G13: 27 | H13: 21-10-2021 | I13: 109851 | J13: 0 | K13: United States | L13: Seattle
... A1001: E03545 | B1001: Sofia Cheng | C1001: Vice President | D1001: Accounting | E1001: Corporate | F1001: Female | G1001: 63 | H1001: 26-07-2020 | I1001: 216195 | J1001: 0.31 | K1001: United States | L1001: Miami

Sheet Organizational Distribution
A1: Search Employee
A5: EEID | C5: Full Name | D5: Job Title | E5: Department | F5: Business Unit | G5: Gender | H5: Ethnicity | I5: Age | J5: Hire Date | K5: Annual Salary | L5: Bonus % | M5: Country | N5: City
A6: E04127 | C6: {=_xlfn.XLOOKUP($A$6,Main!A2:A1001,Main!B2:L1001,"Enter Valid EEID",0)} -> Emery Acosta | D6: Vice President | E6: Sales | F6: Research & Development | G6: Female | H6: 42 | I6: 11-09-2013 | J6: 181452 | K6: 0.3 | L6: United States | M6: Columbus
G9: City | H9: (All)
A10: Department | B10: Count of Employees | D10: Job Title | E10: Count of Employees
A11: Accounting | B11: 96 | D11: Account Representative | E11: 21 | G11: Business Unit_
A12: Engineering | B12: 158 | D12: Analyst | E12: 51 | G12: Department_ | H12: Brazil | I12: China | J12: United States | K12: Grand Total
A13: Finance | B13: 120 | D13: Analyst II | E13: 53 | G13: Accounting | H13: 10 | I13: 20 | J13: 66 | K13: 96
A14: Human Resources | B14: 125 | D14: Automation Engineer | E14: 7 | G14: Engineering | H14: 32 | I14: 29 | J14: 97 | K14: 158
A15: IT | B15: 241 | D15: Business Partner | E15: 19 | G15: Finance | H15: 18 | I15: 28 | J15: 74 | K15: 120
A16: Marketing | B16: 120 | D16: Cloud Infrastructure Architect | E16: 15 | G16: Human Resources | H16: 19 | I16: 25 | J16: 81 | K16: 125
A17: Sales | B17: 140 | D17: Computer Systems Manager | E17: 21 | G17: IT | H17: 26 | I17: 50 | J17: 165 | K17: 241
A18: Grand Total | B18: 1000 | D18: Controls Engineer | E18: 15 | G18: Marketing | H18: 13 | I18: 35 | J18: 72 | K18: 120
D19: Development Engineer | E19: 19 | G19: Sales | H19: 21 | I19: 31 | J19: 88 | K19: 140
D20: Director | E20: 121 | G20: Grand Total | H20: 139 | I20: 218 | J20: 643 | K20: 1000
D21: Engineering Manager | E21: 20
D22: Enterprise Architect | E22: 18
D23: Field Engineer | E23: 21
D24: HRIS Analyst | E24: 16
A25: Business Unit | B25: Count of Employees | D25: IT Coordinator | E25: 11
A26: Corporate | B26: 237 | D26: IT Systems Architect | E26: 12
A27: Manufacturing | B27: 269 | D27: Manager | E27: 98
A28: Research & Development | B28: 229 | D28: Network Administrator | E28: 10
A29: Speciality Products | B29: 265 | D29: Network Architect | E29: 18
D30: Network Engineer | E30: 7
D31: Operations Engineer | E31: 12
D32: Quality Engineer | E32: 20
D33: Service Desk Analyst | E33: 10
D34: Solutions Architect | E34: 15
A35: Total Employees | B35: =COUNTA(Main!A2:A1001) -> 1000 | D35: Sr. Account Representative | E35: 9
A36: Average Age | B36: =AVERAGE(Main!G2:G1001) -> 44.382 | D36: Sr. Analyst | E36: 70
D37: Sr. Business Partner | E37: 17
D38: Sr. Manger | E38: 110
D39: System Administrator | E39: 15
A40: Total Male | B40: =COUNTIF(Main!F2:F1001,"Male") -> 482 | D40: Systems Analyst | E40: 15
A41: Total Female | B41: =COUNTIF(Main!F2:F1001,"Female") -> 518 | D41: Technical Architect | E41: 17
D42: Test Engineer | E42: 12
D43: Vice President | E43: 105
A44: Age Group Distribution
A45: 30–40 | B45: =COUNTIF(Main!G2:G1001,"<=40") -> 384
...

Sheet Salary & Compensation
A1: Salary | H1: COMPENSATION
H3: Business Unit | I3: (All)
A5: Average Salary | B5: =AVERAGE(Main!I2:I1001) -> 113217.37 | I5: Average
I6: Annual Salary. | K6: Bonus %.
A7: Highest Salary | B7: =LARGE(Main!I2:I1001,1) -> 258498 | H7: Department. | I7: Female | J7: Male | K7: Female | L7: Male
A8: Lowest Salary | B8: =SMALL(Main!I2:I1001,1) -> 40063 | H8: Accounting | I8: 130455.25 | J8: 114139.05 | K8: 0.12924528 | L8: 0.089302326
H9: Engineering | I9: 104720.7 | J9: 113460.35 | K9: 0.056875 | L9: 0.086794872
A10: Bonus | B10: =AVERAGE(Table2[Bonus %]) -> 0.08866 | H10: Finance | I10: 122094.78 | J10: 123760.92 | K10: 0.1084058 | L10: 0.11588235
H11: Human Resources | I11: 120208.22 | J11: 115802.93 | K11: 0.11046875 | L11: 0.10393443
H12: IT | I12: 95332.555 | J12: 100187.91 | K12: 0.04907563 | L12: 0.060409836
H13: Marketing | I13: 125366.65 | J13: 133550.24 | K13: 0.11438596 | L13: 0.1331746
H14: Sales | I14: 108929.24 | J14: 113568.09 | K14: 0.081973684 | L14: 0.0859375
A15: Job Title | B15: (All) | H15: Grand Total | I15: 112314.18 | J15: 114188.01 | K15: 0.085984556 | L15: 0.09153527
A17: Bonus %_
A18: Department | B18: Corporate | C18: Manufacturing | D18: Research & Development | E18: Speciality Products | F18: Grand Total
A19: Accounting | B19: 0.14095238 | C19: 0.0925 | D19: 0.11666667 | E19: 0.10482759 | F19: 0.11135417
A20: Engineering | B20: 0.067428571 | C20: 0.095757576 | D20: 0.052325581 | E20: 0.075531915 | F20: 0.07164557
A21: Finance | B21: 0.13512821 | C21: 0.055 | D21: 0.1372 | E21: 0.1125 | F21: 0.11158333
A22: Human Resources | B22: 0.14384615 | C22: 0.087142857 | D22: 0.070714286 | E22: 0.12888889 | F22: 0.10728
A23: IT | B23: 0.045192308 | C23: 0.037926829 | D23: 0.078545455 | E23: 0.065961538 | F23: 0.054813278
A24: Marketing | B24: 0.15322581 | C24: 0.073333333 | D24: 0.12888889 | E24: 0.14 | F24: 0.12425
A25: Sales | B25: 0.085757576 | C25: 0.09969697 | D25: 0.083030303 | E25: 0.07 | F25: 0.083785714
A26: Grand Total | B26: 0.10236287 | C26: 0.070408922 | D26: 0.088646288 | E26: 0.094943396 | F26: 0.08866
A30: Annual Salary_
A31: Department_ | B31: Corporate | C31: Manufacturing | D31: Research & Development | E31: Speciality Products | F31: Grand Total
A32: Accounting | B32: 2794915 | C32: 3223277 | D32: 2126992 | E32: 3676923 | F32: 11822107
A33: Engineering | B33: 3812404 | C33: 3969912 | D33: 4161646 | E33: 5283601 | F33: 17227563
A34: Finance | B34: 5179067 | C34: 2622179 | D34: 3356590 | E34: 3578511 | F34: 14736347
A35: Human Resources | B35: 3658535 | C35: 3630847 | D35: 2845737 | E35: 4622186 | F35: 14757305
A36: IT | B36: 5052094 | C36: 7428581 | D36: 5990757 | E36: 5096067 | F36: 23567499
A37: Marketing | B37: 4332825 | C37: 3127592 | D37: 3655435 | E37: 4443712 | F37: 15559564
A38: Sales | B38: 3794108 | C38: 3879831 | D38: 3623100 | E38: 4249941 | F38: 15546980
A39: Grand Total | B39: 28623948 | C39: 27882219 | D39: 25760257 | E39: 30950941 | F39: 113217365

Sheet Tenure
A1: EEID | B1: Tenure | C1: Job Title | D1: Department | E1: Business Unit | G1: Average Tenure | H1: =AVERAGE(B2:B1001) -> 13.483
A2: E02387 | B2: =DATEDIF(Main!H2,TODAY(),"Y") -> 9 | C2: Sr. Manger | D2: IT | E2: Research & Development
A3: E04105 | B3: =DATEDIF(Main!H3,TODAY(),"Y") -> 28 | C3: Technical Architect | D3: IT | E3: Manufacturing
A4: E02572 | B4: =DATEDIF(Main!H4,TODAY(),"Y") -> 19 | C4: Director | D4: Finance | E4: Speciality Products
A5: E02832 | B5: =DATEDIF(Main!H5,TODAY(),"Y") -> 6 | C5: Computer Systems Manager | D5: IT | E5: Manufacturing
A6: E01639 | B6: =DATEDIF(Main!H6,TODAY(),"Y") -> 30 | C6: Sr. Analyst | D6: Finance | E6: Manufacturing
A7: E00644 | B7: =DATEDIF(Main!H7,TODAY(),"Y") -> 9 | C7: Account Representative | D7: Sales | E7: Corporate
A8: E01550 | B8: =DATEDIF(Main!H8,TODAY(),"Y") -> 5 | C8: Manager | D8: IT | E8: Corporate
A9: E04332 | B9: =DATEDIF(Main!H9,TODAY(),"Y") -> 5 | C9: Analyst | D9: Finance | E9: Manufacturing
A10: E04533 | B10: =DATEDIF(Main!H10,TODAY(),"Y") -> 7 | C10: Manager | D10: Accounting | E10: Manufacturing
A11: E03838 | B11: =DATEDIF(Main!H11,TODAY(),"Y") -> 7 | C11: Sr. Analyst | D11: Finance | E11: Speciality Products | H11: Accounting | J11: Engineering | L11: Finance | N11: Human Resources | P11: IT | R11: Marketing | T11: Sales
A12: E00591 | B12: =DATEDIF(Main!H12,TODAY(),"Y") -> 17 | C12: Sr. Manger | D12: Human Resources | E12: Manufacturing | G12: Country | H12: Average of Bonus % | I12: Average of Annual Salary | J12: Average of Bonus % | K12: Average of Annual Salary | L12: Average of Bonus % | M12: Average of Annual Salary | N12: Average of Bonus % | O12: Average of Annual Salary | P12: Average of Bonus % | Q12: Average of Annual Salary | R12: Average of Bonus % | S12: Average of Annual Salary | T12: Average of Bonus % | U12: Average of Annual Salary
A13: E03344 | B13: =DATEDIF(Main!H13,TODAY(),"Y") -> 4 | C13: Controls Engineer | D13: Engineering | E13: Speciality Products | G13: Brazil | H13: 0.064 | I13: 101789.6 | J13: 0.09125 | K13: 121001.34 | L13: 0.086666667 | M13: 117423.56 | N13: 0.097894737 | O13: 115947.11 | P13: 0.060769231 | Q13: 96025.923 | R13: 0.14923077 | S13: 127670.15 | T13: 0.074285714 | U13: 107152.76
A14: E00530 | B14: =DATEDIF(Main!H14,TODAY(),"Y") -> 27 | C14: Manager | D14: Human Resources | E14: Manufacturing | G14: China | H14: 0.0735 | I14: 109037.25 | J14: 0.067931034 | K14: 107412.62 | L14: 0.11321429 | M14: 127663.21 | N14: 0.1232 | O14: 123367.72 | P14: 0.0532 | Q14: 100321.28 | R14: 0.11885714 | S14: 131570.14 | T14: 0.06483871 | U14: 104452.81
A15: E04239 | B15: =DATEDIF(Main!H15,TODAY(),"Y") -> 4 | C15: Sr. Manger | D15: Finance | E15: Research & Development | G15: United States | H15: 0.13 | I15: 130658.58 | J15: 0.06628866 | K15: 105572.72 | L15: 0.11702703 | M15: 122272.34 | N15: 0.1045679 | O15: 116915.02 | P15: 0.054363636 | Q15: 97301.582 | R15: 0.12236111 | S15: 129095.79 | T15: 0.092727273 | U15: 114303.81
A16: E03496 | B16: =DATEDIF(Main!H16,TODAY(),"Y") -> 8 | C16: Sr. Analyst | D16: Accounting | E16: Speciality Products | G16: Grand Total | H16: 0.11135417 | I16: 123146.95 | J16: 0.07164557 | K16: 109035.21 | L16: 0.11158333 | M16: 122802.89 | N16: 0.10728 | O16: 118058.44 | P16: 0.054813278 | Q16: 97790.452 | R16: 0.12425 | S16: 129663.03 | T16: 0.083785714 | U16: 111049.86
A17: E00549 | B17: =DATEDIF(Main!H17,TODAY(),"Y") -> 13 | C17: Vice President | D17: Marketing | E17: Research & Development
A18: E00163 | B18: =DATEDIF(Main!H18,TODAY(),"Y") -> 24 | C18: Director | D18: Finance | E18: Research & Development
A19: E00884 | B19: =DATEDIF(Main!H19,TODAY(),"Y") -> 22 | C19: Sr. Manger | D19: Marketing | E19: Speciality Products
A20: E04116 | B20: =DATEDIF(Main!H20,TODAY(),"Y") -> 12 | C20: Director | D20: IT | E20: Corporate
A21: E04625 | B21: =DATEDIF(Main!H21,TODAY(),"Y") -> 23 | C21: Director | D21: Sales | E21: Research & Development
A22: E03680 | B22: =DATEDIF(Main!H22,TODAY(),"Y") -> 14 | C22: Sr. Manger | D22: IT | E22: Manufacturing
A23: E04732 | B23: =DATEDIF(Main!H23,TODAY(),"Y") -> 5 | C23: Director | D23: Sales | E23: Manufacturing
A24: E03484 | B24: =DATEDIF(Main!H24,TODAY(),"Y") -> 23 | C24: Director | D24: IT | E24: Research & Development
A25: E00671 | B25: =DATEDIF(Main!H25,TODAY(),"Y") -> 6 | C25: Analyst | D25: Sales | E25: Speciality Products
A26: E02071 | B26: =DATEDIF(Main!H26,TODAY(),"Y") -> 12 | C26: Vice President | D26: Sales | E26: Speciality Products
A27: E02206 | B27: =DATEDIF(Main!H27,TODAY(),"Y") -> 10 | C27: Director | D27: Human Resources | E27: Speciality Products
A28: E04545 | B28: =DATEDIF(Main!H28,TODAY(),"Y") -> 21 | C28: Quality Engineer | D28: Engineering | E28: Corporate
... A1001: E03545 | B1001: =DATEDIF(Main!H1001,TODAY(),"Y") -> 5 | C1001: Vice President | D1001: Accounting | E1001: Corporate

Sheet Charts
A5: Row Labels | B5: Count of EEID
A6: Female | B6: 518
A7: Male | B7: 482
A8: Grand Total | B8: 1000
A20: Row Labels | B20: Average of Annual Salary
A21: Accounting | B21: 123146.95
A22: Engineering | B22: 109035.21
A23: Finance | B23: 122802.89
A24: Human Resources | B24: 118058.44
A25: IT | B25: 97790.452
A26: Marketing | B26: 129663.03
A27: Sales | B27: 111049.86
A28: Grand Total | B28: 113217.37
A40: Count of Hire Date | B40: Column Labels
A41: Row Labels | B41: Female | C41: Male | D41: Grand Total
A42: Accounting | B42: 53 | C42: 43 | D42: 96
A43: Engineering | B43: 80 | C43: 78 | D43: 158
A44: Finance | B44: 69 | C44: 51 | D44: 120
A45: Human Resources | B45: 64 | C45: 61 | D45: 125
A46: IT | B46: 119 | C46: 122 | D46: 241
A47: Marketing | B47: 57 | C47: 63 | D47: 120
A48: Sales | B48: 76 | C48: 64 | D48: 140
A49: Grand Total | B49: 518 | C49: 482 | D49: 1000
A60: City | B60: (All)
A62: Count of EEID | B62: Column Labels
A63: Row Labels | B63: Female | C63: Male | D63: Grand Total
A64: Brazil | B64: 75 | C64: 64 | D64: 139
A65: China | B65: 109 | C65: 109 | D65: 218
A66: United States | B66: 334 | C66: 309 | D66: 643
A67: Grand Total | B67: 518 | C67: 482 | D67: 1000
A80: Count of EEID | B80: Column Labels
A81: Row Labels | B81: Accounting | C81: Engineering | D81: Finance | E81: Human Resources | F81: IT | G81: Marketing | H81: Sales | I81: Grand Total
A82: Corporate | B82: 21 | C82: 35 | D82: 39 | E82: 26 | F82: 52 | G82: 31 | H82: 33 | I82: 237
A83: Manufacturing | B83: 28 | C83: 33 | D83: 28 | E83: 35 | F83: 82 | G83: 30 | H83: 33 | I83: 269
A84: Research & Development | B84: 18 | C84: 43 | D84: 25 | E84: 28 | F84: 55 | G84: 27 | H84: 33 | I84: 229
A85: Speciality Products | B85: 29 | C85: 47 | D85: 28 | E85: 36 | F85: 52 | G85: 32 | H85: 41 | I85: 265
A86: Grand Total | B86: 96 | C86: 158 | D86: 120 | E86: 125 | F86: 241 | G86: 120 | H86: 140 | I86: 1000

Sheet Slicer
A1: Row Labels | B1: Count of EEID
A2: Accounting | B2: 96
A3: Engineering | B3: 158
A4: Finance | B4: 120
A5: Human Resources | B5: 125
A6: IT | B6: 241
A7: Marketing | B7: 120
A8: Sales | B8: 140
A9: Grand Total | B9: 1000

Sheet Detail1
A1: Details for Average of Annual Salary - Department: Finance, Gender: Male
A3: EEID | B3: Full Name | C3: Job Title | D3: Department | E3: Business Unit | F3: Gender | G3: Age | H3: Hire Date | I3: Annual Salary | J3: Bonus % | K3: Country | L3: City
A4: E03349 | B4: Dylan Chin | C4: Director | D4: Finance | E4: Corporate | F4: Male | G4: 60 | H4: 05-06-2017 | I4: 158898 | J4: 0.18 | K4: United States | L4: Miami
A5: E04415 | B5: Leonardo Luong | C5: Manager | D5: Finance | E5: Manufacturing | F5: Male | G5: 52 | H5: 29-12-1999 | I5: 116527 | J5: 0.07 | K5: United States | L5: Phoenix
A6: E02684 | B6: Aaron Maldonado | C6: Analyst II | D6: Finance | E6: Manufacturing | F6: Male | G6: 39 | H6: 17-09-2008 | I6: 62861 | J6: 0 | K6: United States | L6: Seattle
A7: E01338 | B7: Jaxson Coleman | C7: Manager | D7: Finance | E7: Manufacturing | F7: Male | G7: 32 | H7: 15-04-2020 | I7: 126671 | J7: 0.09 | K7: United States | L7: Miami
A8: E01639 | B8: Austin Vo | C8: Sr. Analyst | D8: Finance | E8: Manufacturing | F8: Male | G8: 55 | H8: 20-11-1995 | I8: 95409 | J8: 0 | K8: United States | L8: Phoenix
A9: E03106 | B9: Xavier Davis | C9: Vice President | D9: Finance | E9: Corporate | F9: Male | G9: 36 | H9: 17-01-2009 | I9: 238236 | J9: 0.31 | K9: United States | L9: Seattle
A10: E00225 | B10: Angel Delgado | C10: Director | D10: Finance | E10: Corporate | F10: Male | G10: 31 | H10: 10-08-2017 | I10: 156931 | J10: 0.28 | K10: United States | L10: Seattle
A11: E04332 | B11: Luke Martin | C11: Analyst | D11: Finance | E11: Manufacturing | F11: Male | G11: 25 | H11: 16-05-2020 | I11: 41336 | J11: 0 | K11: United States | L11: Miami
A12: E01337 | B12: Andrew Coleman | C12: Director | D12: Finance | E12: Corporate | F12: Male | G12: 41 | H12: 15-05-2019 | I12: 174415 | J12: 0.23 | K12: United States | L12: Miami
A13: E03055 | B13: Austin Rojas | C13: Vice President | D13: Finance | E13: Corporate | F13: Male | G13: 29 | H13: 05-12-2018 | I13: 199504 | J13: 0.3 | K13: United States | L13: Austin
A14: E01832 | B14: Ezra Singh | C14: Analyst | D14: Finance | E14: Manufacturing | F14: Male | G14: 56 | H14: 10-05-2006 | I14: 41561 | J14: 0 | K14: United States | L14: Austin
A15: E00342 | B15: Wesley Doan | C15: Manager | D15: Finance | E15: Corporate | F15: Male | G15: 63 | H15: 19-04-2004 | I15: 122487 | J15: 0.08 | K15: China | L15: Shanghai
... A54: E00254 | B54: Samuel Morales | C54: Analyst II | D54: Finance | E54: Corporate | F54: Male | G54: 34 | H54: 27-06-2015 | I54: 57008 | J54: 0 | K54: United States | L54: Phoenix
